Workbook

Sheet Poderevka-2_2025-10-27-14-35-37
A1: N | B1: Y | C1: X | D1: Z | E1: обхват | F1: code | G1: name | H1: komment
A2: 1 | B2: 43.025452577 | C2: 131.895595640 | D2: 44.85 | E2: 70 | F2: 1 | G2: Tilia mandshurica | I2: 1 | J2: Tilia mandshurica | K2: =COUNTIF(G:G, "Tilia mandshurica") -> 1
A3: 2 | B3: 43.025511469 | C3: 131.895668666 | D3: 44.177 | E3: 15 | F3: 3 | G3: Fraxinus chinensis | I3: 2 | J3: Tilia amurensis | K3: =COUNTIF(G:G, "Tilia amurensis") -> 33
A4: 3 | B4: 43.025551260 | C4: 131.895614984 | D4: 43.721 | E4: 92 | F4: 4 | G4: Fraxinus mandshurica | I4: 3 | J4: Fraxinus chinensis | K4: =COUNTIF(G:G, "Fraxinus chinensis") -> 28
A5: 4 | B5: 43.025595927 | C5: 131.895641729 | D5: 43.442 | E5: 36 | F5: 8 | G5: Betula davurica | I5: 4 | J5: Fraxinus mandshurica | K5: =COUNTIF(G:G, "Fraxinus mandshurica") -> 13
A6: 5 | B6: 43.025603112 | C6: 131.895653882 | D6: 43.252 | E6: 29;22 | F6: 11 | G6: Juglans mandshurica | I6: 5 | J6: Alnus hirsuta | K6: =COUNTIF(G:G, "Alnus hirsuta") -> 48
A7: 6 | B7: 43.025597256 | C7: 131.895704018 | D7: 43.326 | E7: 72 | F7: 2 | G7: Tilia amurensis | I7: 6 | J7: Alnus japonica | K7: =COUNTIF(G:G, "Alnus japonica") -> 6
A8: 7 | B8: 43.025574907 | C8: 131.895745726 | D8: 43.781 | E8: 72.5 | F8: 3 | G8: Fraxinus chinensis | I8: 7 | J8: Betula platyphyla | K8: =COUNTIF(G:G, "Betula platyphyla") -> 44 | L8: плюс 1
A9: 8 | B9: 43.025602630 | C9: 131.895772578 | D9: 43.454 | E9: 91 | F9: 7 | G9: Betula platyphyla | I9: 8 | J9: Betula davurica | K9: =COUNTIF(G:G, "Betula davurica") -> 25 | L9: плюс 1
A10: 9 | B10: 43.025581225 | C10: 131.895791547 | D10: 43.68 | E10: 89 | F10: 8 | G10: Betula davurica | I10: 9 | J10: Quercus mongolica | K10: =COUNTIF(G:G, "Quercus mongolica") -> 63
A11: 10 | B11: 43.025644545 | C11: 131.895796388 | D11: 43.172 | E11: 31,5;24;29,5 | F11: 7 | G11: Betula platyphyla | I11: 10 | J11: Maackia amurensis | K11: =COUNTIF(G:G, "Maackia amurensis") -> 5
A12: 11 | B12: 43.025638538 | C12: 131.895864550 | D12: 43.287 | E12: 35,5;37,5 | F12: 7 | G12: Betula platyphyla | I12: 11 | J12: Juglans mandshurica | K12: =COUNTIF(G:G, "Juglans mandshurica") -> 19 | L12: плюс 1
A13: 12 | B13: 43.025641977 | C13: 131.895860636 | D13: 43.376 | E13: 32;27;29 | F13: 7 | G13: Betula platyphyla | I13: 12 | J13: Acer mono | K13: =COUNTIF(G:G, "Acer mono") -> 1
A14: 13 | B14: 43.025673908 | C14: 131.895908276 | D14: 42.927 | E14: 86;81 | F14: 9 | G14: Quercus mongolica | I14: 13 | J14: Kalopanax septemlobus | K14: =COUNTIF(G:G, "Kalopanax septemlobus") -> 11
A15: 14 | B15: 43.025745523 | C15: 131.895852528 | D15: 42.148 | E15: 81;89 | F15: 9 | G15: Quercus mongolica | I15: 14 | J15: Cerasus maximowiczii | K15: =COUNTIF(G:G, "Cerasus maximowiczii") -> 1
A16: 15 | B16: 43.025758291 | C16: 131.895848120 | D16: 41.958 | E16: 40 | F16: 5 | G16: Alnus hirsuta | I16: 15 | J16: Salix caprea | K16: =COUNTIF(G:G, "Salix caprea") -> 23
A17: 16 | B17: 43.025800699 | C17: 131.895919938 | D17: 41.555 | E17: 138 | F17: 9 | G17: Quercus mongolica | I17: 16 | J17: Aralia elata | K17: =COUNTIF(G:G, "Aralia elata") -> 19
A18: 17 | B18: 43.025837067 | C18: 131.895915053 | D18: 41.174 | E18: 35 | F18: 5 | G18: Alnus hirsuta | I18: 17 | J18: Phellodendron amurensis | K18: =COUNTIF(G:G, "Phellodendron amurensis") -> 4 | L18: плюс 1
A19: 18 | B19: 43.025841622 | C19: 131.895902939 | D19: 41.132 | E19: 103 | F19: 9 | G19: Quercus mongolica | I19: 18 | J19: Salix schwerinii
A20: 19 | B20: 43.025812405 | C20: 131.896005569 | D20: 41.324 | E20: 83 | F20: 9 | G20: Quercus mongolica | I20: 19 | J20: Cerasus sargentii
A21: 20 | B21: 43.025835541 | C21: 131.896007089 | D21: 40.945 | E21: 138 | F21: 2 | G21: Tilia amurensis | I21: 20 | J21: Acer tataricum
A22: 21 | B22: 43.025844423 | C22: 131.896062547 | D22: 40.363 | E22: 91 | F22: 12 | G22: Acer mono | I22: 21 | J22: Acer tegmentosum
A23: 22 | B23: 43.025753581 | C23: 131.896154906 | D23: 41.97 | E23: 167 | F23: 8 | G23: Betula davurica | I23: 22 | J23: Carpinus cordata
A24: 23 | B24: 43.025733772 | C24: 131.896063930 | D24: 42.689 | E24: 149 | F24: 9 | G24: Quercus mongolica | I24: 23 | J24: Acer pseudosieboldianum
A25: 24 | B25: 43.025712034 | C25: 131.895938431 | D25: 42.501 | E25: 126 | F25: 9 | G25: Quercus mongolica | I25: 24 | J25: Salix gracilistyla
A26: 25 | B26: 43.025662998 | C26: 131.895984834 | D26: 43.073 | E26: 100 | F26: 9 | G26: Quercus mongolica | I26: 25 | J26: Salix nipponica
A27: 26 | B27: 43.025669584 | C27: 131.896063417 | D27: 43.112 | E27: 102;129 | F27: 2 | G27: Tilia amurensis
A28: 27 | B28: 43.025622224 | C28: 131.896142622 | D28: 43.735 | E28: 70 | F28: 3 | G28: Fraxinus chinensis
A29: 28 | B29: 43.025604385 | C29: 131.896141322 | D29: 44.008 | E29: 118 | F29: 8 | G29: Betula davurica
A30: 29 | B30: 43.025601087 | C30: 131.896162601 | D30: 44.141 | E30: 95 | F30: 9 | G30: Quercus mongolica
A31: 30 | B31: 43.025575730 | C31: 131.896085535 | D31: 44.21 | E31: 105 | F31: 9 | G31: Quercus mongolica
A32: 31 | B32: 43.025573609 | C32: 131.895973795 | D32: 44.155 | E32: 111 | F32: 9 | G32: Quercus mongolica
A33: 32 | B33: 43.025614947 | C33: 131.895897773 | D33: 43.427 | E33: 30 | F33: 5 | G33: Alnus hirsuta
A34: 33 | B34: 43.025522673 | C34: 131.895813098 | D34: 44.388 | E34: 118 | F34: 9 | G34: Quercus mongolica
A35: 34 | B35: 43.025506495 | C35: 131.895779548 | D35: 44.404 | E35: 20 | F35: 5 | G35: Alnus hirsuta
A36: 35 | B36: 43.025552840 | C36: 131.896117923 | D36: 44.539 | E36: 133 | F36: 9 | G36: Quercus mongolica
A37: 36 | B37: 43.025539977 | C37: 131.896192993 | D37: 44.818 | E37: 210 | F37: 13 | G37: Kalopanax septemlobus | H37: мертв
A38: 37 | B38: 43.025514413 | C38: 131.896128664 | D38: 44.845 | E38: 84;85 | F38: 9 | G38: Quercus mongolica
A39: 38 | B39: 43.025476270 | C39: 131.896206424 | D39: 44.953 | E39: 100;78 | F39: 9 | G39: Quercus mongolica
A40: 39 | B40: 43.025432257 | C40: 131.896109305 | D40: 45.782 | E40: 97;100 | F40: 9 | G40: Quercus mongolica
...

Sheet Лист1
A1: 332 | B1: 43.025909066 | C1: 131.895920687 | D1: 40.548
A2: 333 | B2: 43.025946167 | C2: 131.895878027 | D2: 40.096
A3: 334 | B3: 43.026009552 | C3: 131.895813430 | D3: 39.488
A4: 335 | B4: 43.026013271 | C4: 131.895803916 | D4: 39.571
A5: 336 | B5: 43.026010794 | C5: 131.895780104 | D5: 39.403
A6: 337 | B6: 43.026008841 | C6: 131.895765415 | D6: 39.842
A7: 338 | B7: 43.026013395 | C7: 131.895796357 | D7: 39.541
A8: 339 | B8: 43.026023392 | C8: 131.895843119 | D8: 38.847
A9: 340 | B9: 43.026024861 | C9: 131.895843412 | D9: 38.983
A10: 341 | B10: 43.026041002 | C10: 131.895839334 | D10: 38.892
A11: 342 | B11: 43.026040513 | C11: 131.895841999 | D11: 38.711
A12: 343 | B12: 43.026003749 | C12: 131.895894065 | D12: 38.707
... A61: 392 | B61: 43.026443759 | C61: 131.895887633 | D61: 35.789

Sheet Лист2
A2: Tilia mandshurica | B2: 1
A3: Tilia amurensis | B3: 2
A4: Fraxinus chinensis | B4: 3
A5: Fraxinus mandshurica | B5: 4
A6: Alnus hirsuta | B6: 5
A7: Alnus japonica | B7: 6
A8: Betula platyphyla | B8: 7
A9: Betula davurica | B9: 8
A10: Quercus mongolica | B10: 9
A11: Maackia amurensis | B11: 10
A12: Juglans mandshurica | B12: 11
A13: Acer mono | B13: 12
... A26: Salix nipponica | B26: 25
